Workbook

Sheet Read Me
A1: K-30 / Measure DI — AMC & Spare Parts Opportunity Model
A2: Client-wise, product-wise aftermarket (AMC + Spare Parts) revenue opportunity sizing, Year 1–7
A4: WHAT THIS WORKBOOK DOES
A5: For every product sold to every client (source: K30_Spare_Data.xlsx), this model estimates the Annual Maintenance
A6: Contract (AMC) and Spare Parts revenue opportunity for Years 1 through 7 after sale, as a % of that product's
A7: original billed value. The % curve is an editable assumption (see the "AMC & Spares % Assumptions" tab) — every
A8: opportunity value in this workbook is a LIVE FORMULA, so changing a % or a billed value recalculates everything.
A10: HOW TO USE IT
A11: 1. Open "Client-Product Master" and fill in any blank Product Billed Value, Installation Year, or Warranty Status
A12: cells (shaded yellow) as that information becomes available.
A13: 2. Open "AMC & Spares % Assumptions" and adjust the Year 1–7 % curve to match your actual AMC/Spares pricing
A14: policy once you have real billing history to calibrate against — the starting values here are an industry-pattern
... A46: data as soon as that is available, for a far more accurate forecast.

Sheet AMC & Spares % Assumptions
A1: AMC & Spare Parts — Year 1–7 Opportunity % of Original Product Billed Value
A2: Editable assumption — see "Read Me" tab for methodology. Adjust once real AMC/Spares billing history is available.
A4: Year After Sale | B4: AMC Opportunity (% of Product Value) | C4: Spares Opportunity (% of Product Value) | D4: Combined Aftermarket Opportunity (%)
A5: Year 1 | B5: 0.015 | C5: 0.01 | D5: =B5+C5 -> 0.025
A6: Year 2 | B6: 0.03 | C6: 0.025 | D6: =B6+C6 -> 0.055
A7: Year 3 | B7: 0.045 | C7: 0.045 | D7: =B7+C7 -> 0.09
A8: Year 4 | B8: 0.055 | C8: 0.06 | D8: =B8+C8 -> 0.115
A9: Year 5 | B9: 0.06 | C9: 0.075 | D9: =B9+C9 -> 0.135
A10: Year 6 | B10: 0.065 | C10: 0.085 | D10: =B10+C10 -> 0.15
A11: Year 7 | B11: 0.07 | C11: 0.095 | D11: =B11+C11 -> 0.165
A12: 7-Year Cumulative | B12: =SUM(B5:B11) -> 0.34 | C12: =SUM(C5:C11) -> 0.395 | D12: =SUM(D5:D11) -> 0.735

Sheet Client-Product Master
A1: # | B1: Client Name | C1: Product / Equipment Description | D1: Segment (as per source) | E1: Product Billed Value (INR) | F1: Installation Year | G1: Warranty Status
A2: 1 | B2: Jindal Steel & Power Limited | C2: Wagon Bulge | D2: Spare
A3: 2 | B3: ISMT LIMITED | C3: 100 Ton Ladle Transfer Car Weighing System | D3: Spare
A4: 3 | B4: NTPC | C4: STATIC WEIGH BRIDGES | D4: Spare
A5: 4 | B5: MAgna Casting & Machine Works Pvt | C5: 50 Ton Ladle Transfer Car Weighing System | D5: Spare
A6: 5 | B6: Tata Steel Long products limited | C6: WEIGHBRIDGE STRUCTURE,100 MT,18X3M | D6: Spare
A7: 6 | B7: Hospet Steels Limited | C7: Hot metal weighing system 100 ton | D7: Spare
A8: 7 | B8: Tata Steel Long products limited | C8: COIL WEIGHING SYSTEM- 5MT | D8: Spare
A9: 8 | B9: JAYASWAL NECO INDUSTRIES LIMITED | C9: TUNDISH WEIGHING SYSTEM | D9: Spare
A10: 9 | B10: JAYASWAL NECO INDUSTRIES LIMITED | C10: TUNDISH CAR WEIGHING SYSTEM | D10: Spare
A11: 10 | B11: FRIGATE TEKNOLOGIES PRIVATE LIMITED | C11: Rail Static weigh Bridge | D11: Spare
A12: 11 | B12: NTPC solapur | C12: Rail Static Weighing System | D12: Spare
A13: 12 | B13: BAJAJ MUKAND LTD | C13: BILLET WEIGHING SYSTEM 3 TON | D13: Spare
... A38: 37 | B38: EVONITH VALUE STEEL LIMITED | C38: SAP integration charges along with service engineer service charges | D38: Spare
A39: 38 | B39: Ultratech Cement Ltd, Unit- Maihar cement works | C39: (Product description not provided in source - confirm) | D39: Spare | E39: 550000
A40: 39 | B40: JINDAL STAINLESS LIMITED | C40: Junction Box | D40: Spare | E40: 22000
A41: 40 | B41: Evonith Steel Complex | C41: Spare for Crane Scale | D41: Spare | E41: 295000
A42: 41 | B42: JSW Steel Ltd. | C42: CONTROLLER & LOAD CELL | D42: Spare | E42: 113000
A43: 42 | B43: JSW Steel Limited | C43: Bin Load cell and Controller | D43: Spare | E43: 90000
A44: 43 | B44: JSW STEEL-SALEM | C44: SPARE For WAGON TIPPLER | D44: Spare | E44: 930000
A45: 44 | B45: Balaji Engineers & Contractors. | C45: 6 TON WEIGH SCALE SPARRE | D45: Spare | E45: 333250
A46: 45 | B46: ELECTRO PNEUMATICS AND HYDRAULICS (INDIA) PVT LTD | C46: Load cell required for existing weighing system of Wagon Tipplers | D46: Spare
A47: 46 | B47: JSW Steel Limited | C47: Weigh bridges Spare | D47: Spare
A48: 47 | B48: JSW BPSL | C48: SPARE OFFER FOR STEEL RAIL WEIGHING SYSTEM | D48: Spare | E48: 870000
A49: 48 | B49: Kirloskar Ferrous Industries Ltd Steel Plant | C49: LOAD CELL SPARES OFFER FOR 200-TON LADLE WEIGH BRIDGE | D49: Spare | E49: 400000
A50: 49 | B50: TAMILIIADU CEMENTS CORPORATION LTD | C50: Spares For Bloom Weighing System | D50: Spare | E50: 675000
A51: 50 | B51: JSW JFE Steel Limited | C51: in motion Weighbridge | D51: Spare | E51: 860000
A52: 51 | B52: JSW Steel Limited | C52: Load Cell signal monitoring system | D52: Spare
A53: 52 | B53: Synergy Steels Limited | C53: SPARE FOR PITLESS WAGON TIPPLER WEIGHING SYSTEM | D53: Spare
A54: 53 | B54: adani gondia | C54: Load Sensor | D54: Spare | E54: 165000
A55: 54 | B55: (Client name not provided in source - confirm) | C55: 8 no load cell | D55: Spare | E55: 660000

Sheet Opportunity Model (Year-wise)
A1: Client Name | B1: Product / Equipment Description | C1: Product Billed Value (INR) | D1: Year After Sale | E1: AMC Opportunity % | F1: AMC Opportunity Value (INR) | G1: Spares Opportunity % | H1: Spares Opportunity Value (INR) | I1: Total Aftermarket Opportunity (INR)
A2: ='Client-Product Master'!B2 -> Jindal Steel & Power Limited | B2: ='Client-Product Master'!C2 -> Wagon Bulge | C2: ='Client-Product Master'!E2 -> 0 | D2: 1 | E2: =INDEX('AMC & Spares % Assumptions'!$B$5:$B$11, D2) -> 0.015 | F2: =C2*E2 -> 0 | G2: =INDEX('AMC & Spares % Assumptions'!$C$5:$C$11, D2) -> 0.01 | H2: =C2*G2 -> 0 | I2: =F2+H2 -> 0
A3: ='Client-Product Master'!B2 -> Jindal Steel & Power Limited | B3: ='Client-Product Master'!C2 -> Wagon Bulge | C3: ='Client-Product Master'!E2 -> 0 | D3: 2 | E3: =INDEX('AMC & Spares % Assumptions'!$B$5:$B$11, D3) -> 0.03 | F3: =C3*E3 -> 0 | G3: =INDEX('AMC & Spares % Assumptions'!$C$5:$C$11, D3) -> 0.025 | H3: =C3*G3 -> 0 | I3: =F3+H3 -> 0
A4: ='Client-Product Master'!B2 -> Jindal Steel & Power Limited | B4: ='Client-Product Master'!C2 -> Wagon Bulge | C4: ='Client-Product Master'!E2 -> 0 | D4: 3 | E4: =INDEX('AMC & Spares % Assumptions'!$B$5:$B$11, D4) -> 0.045 | F4: =C4*E4 -> 0 | G4: =INDEX('AMC & Spares % Assumptions'!$C$5:$C$11, D4) -> 0.045 | H4: =C4*G4 -> 0 | I4: =F4+H4 -> 0
A5: ='Client-Product Master'!B2 -> Jindal Steel & Power Limited | B5: ='Client-Product Master'!C2 -> Wagon Bulge | C5: ='Client-Product Master'!E2 -> 0 | D5: 4 | E5: =INDEX('AMC & Spares % Assumptions'!$B$5:$B$11, D5) -> 0.055 | F5: =C5*E5 -> 0 | G5: =INDEX('AMC & Spares % Assumptions'!$C$5:$C$11, D5) -> 0.06 | H5: =C5*G5 -> 0 | I5: =F5+H5 -> 0
A6: ='Client-Product Master'!B2 -> Jindal Steel & Power Limited | B6: ='Client-Product Master'!C2 -> Wagon Bulge | C6: ='Client-Product Master'!E2 -> 0 | D6: 5 | E6: =INDEX('AMC & Spares % Assumptions'!$B$5:$B$11, D6) -> 0.06 | F6: =C6*E6 -> 0 | G6: =INDEX('AMC & Spares % Assumptions'!$C$5:$C$11, D6) -> 0.075 | H6: =C6*G6 -> 0 | I6: =F6+H6 -> 0
A7: ='Client-Product Master'!B2 -> Jindal Steel & Power Limited | B7: ='Client-Product Master'!C2 -> Wagon Bulge | C7: ='Client-Product Master'!E2 -> 0 | D7: 6 | E7: =INDEX('AMC & Spares % Assumptions'!$B$5:$B$11, D7) -> 0.065 | F7: =C7*E7 -> 0 | G7: =INDEX('AMC & Spares % Assumptions'!$C$5:$C$11, D7) -> 0.085 | H7: =C7*G7 -> 0 | I7: =F7+H7 -> 0
A8: ='Client-Product Master'!B2 -> Jindal Steel & Power Limited | B8: ='Client-Product Master'!C2 -> Wagon Bulge | C8: ='Client-Product Master'!E2 -> 0 | D8: 7 | E8: =INDEX('AMC & Spares % Assumptions'!$B$5:$B$11, D8) -> 0.07 | F8: =C8*E8 -> 0 | G8: =INDEX('AMC & Spares % Assumptions'!$C$5:$C$11, D8) -> 0.095 | H8: =C8*G8 -> 0 | I8: =F8+H8 -> 0
A9: ='Client-Product Master'!B3 -> ISMT LIMITED | B9: ='Client-Product Master'!C3 -> 100 Ton Ladle Transfer Car Weighing System | C9: ='Client-Product Master'!E3 -> 0 | D9: 1 | E9: =INDEX('AMC & Spares % Assumptions'!$B$5:$B$11, D9) -> 0.015 | F9: =C9*E9 -> 0 | G9: =INDEX('AMC & Spares % Assumptions'!$C$5:$C$11, D9) -> 0.01 | H9: =C9*G9 -> 0 | I9: =F9+H9 -> 0
A10: ='Client-Product Master'!B3 -> ISMT LIMITED | B10: ='Client-Product Master'!C3 -> 100 Ton Ladle Transfer Car Weighing System | C10: ='Client-Product Master'!E3 -> 0 | D10: 2 | E10: =INDEX('AMC & Spares % Assumptions'!$B$5:$B$11, D10) -> 0.03 | F10: =C10*E10 -> 0 | G10: =INDEX('AMC & Spares % Assumptions'!$C$5:$C$11, D10) -> 0.025 | H10: =C10*G10 -> 0 | I10: =F10+H10 -> 0
A11: ='Client-Product Master'!B3 -> ISMT LIMITED | B11: ='Client-Product Master'!C3 -> 100 Ton Ladle Transfer Car Weighing System | C11: ='Client-Product Master'!E3 -> 0 | D11: 3 | E11: =INDEX('AMC & Spares % Assumptions'!$B$5:$B$11, D11) -> 0.045 | F11: =C11*E11 -> 0 | G11: =INDEX('AMC & Spares % Assumptions'!$C$5:$C$11, D11) -> 0.045 | H11: =C11*G11 -> 0 | I11: =F11+H11 -> 0
A12: ='Client-Product Master'!B3 -> ISMT LIMITED | B12: ='Client-Product Master'!C3 -> 100 Ton Ladle Transfer Car Weighing System | C12: ='Client-Product Master'!E3 -> 0 | D12: 4 | E12: =INDEX('AMC & Spares % Assumptions'!$B$5:$B$11, D12) -> 0.055 | F12: =C12*E12 -> 0 | G12: =INDEX('AMC & Spares % Assumptions'!$C$5:$C$11, D12) -> 0.06 | H12: =C12*G12 -> 0 | I12: =F12+H12 -> 0
A13: ='Client-Product Master'!B3 -> ISMT LIMITED | B13: ='Client-Product Master'!C3 -> 100 Ton Ladle Transfer Car Weighing System | C13: ='Client-Product Master'!E3 -> 0 | D13: 5 | E13: =INDEX('AMC & Spares % Assumptions'!$B$5:$B$11, D13) -> 0.06 | F13: =C13*E13 -> 0 | G13: =INDEX('AMC & Spares % Assumptions'!$C$5:$C$11, D13) -> 0.075 | H13: =C13*G13 -> 0 | I13: =F13+H13 -> 0
A14: ='Client-Product Master'!B3 -> ISMT LIMITED | B14: ='Client-Product Master'!C3 -> 100 Ton Ladle Transfer Car Weighing System | C14: ='Client-Product Master'!E3 -> 0 | D14: 6 | E14: =INDEX('AMC & Spares % Assumptions'!$B$5:$B$11, D14) -> 0.065 | F14: =C14*E14 -> 0 | G14: =INDEX('AMC & Spares % Assumptions'!$C$5:$C$11, D14) -> 0.085 | H14: =C14*G14 -> 0 | I14: =F14+H14 -> 0
A15: ='Client-Product Master'!B3 -> ISMT LIMITED | B15: ='Client-Product Master'!C3 -> 100 Ton Ladle Transfer Car Weighing System | C15: ='Client-Product Master'!E3 -> 0 | D15: 7 | E15: =INDEX('AMC & Spares % Assumptions'!$B$5:$B$11, D15) -> 0.07 | F15: =C15*E15 -> 0 | G15: =INDEX('AMC & Spares % Assumptions'!$C$5:$C$11, D15) -> 0.095 | H15: =C15*G15 -> 0 | I15: =F15+H15 -> 0
A16: ='Client-Product Master'!B4 -> NTPC | B16: ='Client-Product Master'!C4 -> STATIC WEIGH BRIDGES | C16: ='Client-Product Master'!E4 -> 0 | D16: 1 | E16: =INDEX('AMC & Spares % Assumptions'!$B$5:$B$11, D16) -> 0.015 | F16: =C16*E16 -> 0 | G16: =INDEX('AMC & Spares % Assumptions'!$C$5:$C$11, D16) -> 0.01 | H16: =C16*G16 -> 0 | I16: =F16+H16 -> 0
A17: ='Client-Product Master'!B4 -> NTPC | B17: ='Client-Product Master'!C4 -> STATIC WEIGH BRIDGES | C17: ='Client-Product Master'!E4 -> 0 | D17: 2 | E17: =INDEX('AMC & Spares % Assumptions'!$B$5:$B$11, D17) -> 0.03 | F17: =C17*E17 -> 0 | G17: =INDEX('AMC & Spares % Assumptions'!$C$5:$C$11, D17) -> 0.025 | H17: =C17*G17 -> 0 | I17: =F17+H17 -> 0
A18: ='Client-Product Master'!B4 -> NTPC | B18: ='Client-Product Master'!C4 -> STATIC WEIGH BRIDGES | C18: ='Client-Product Master'!E4 -> 0 | D18: 3 | E18: =INDEX('AMC & Spares % Assumptions'!$B$5:$B$11, D18) -> 0.045 | F18: =C18*E18 -> 0 | G18: =INDEX('AMC & Spares % Assumptions'!$C$5:$C$11, D18) -> 0.045 | H18: =C18*G18 -> 0 | I18: =F18+H18 -> 0
A19: ='Client-Product Master'!B4 -> NTPC | B19: ='Client-Product Master'!C4 -> STATIC WEIGH BRIDGES | C19: ='Client-Product Master'!E4 -> 0 | D19: 4 | E19: =INDEX('AMC & Spares % Assumptions'!$B$5:$B$11, D19) -> 0.055 | F19: =C19*E19 -> 0 | G19: =INDEX('AMC & Spares % Assumptions'!$C$5:$C$11, D19) -> 0.06 | H19: =C19*G19 -> 0 | I19: =F19+H19 -> 0
A20: ='Client-Product Master'!B4 -> NTPC | B20: ='Client-Product Master'!C4 -> STATIC WEIGH BRIDGES | C20: ='Client-Product Master'!E4 -> 0 | D20: 5 | E20: =INDEX('AMC & Spares % Assumptions'!$B$5:$B$11, D20) -> 0.06 | F20: =C20*E20 -> 0 | G20: =INDEX('AMC & Spares % Assumptions'!$C$5:$C$11, D20) -> 0.075 | H20: =C20*G20 -> 0 | I20: =F20+H20 -> 0
A21: ='Client-Product Master'!B4 -> NTPC | B21: ='Client-Product Master'!C4 -> STATIC WEIGH BRIDGES | C21: ='Client-Product Master'!E4 -> 0 | D21: 6 | E21: =INDEX('AMC & Spares % Assumptions'!$B$5:$B$11, D21) -> 0.065 | F21: =C21*E21 -> 0 | G21: =INDEX('AMC & Spares % Assumptions'!$C$5:$C$11, D21) -> 0.085 | H21: =C21*G21 -> 0 | I21: =F21+H21 -> 0
A22: ='Client-Product Master'!B4 -> NTPC | B22: ='Client-Product Master'!C4 -> STATIC WEIGH BRIDGES | C22: ='Client-Product Master'!E4 -> 0 | D22: 7 | E22: =INDEX('AMC & Spares % Assumptions'!$B$5:$B$11, D22) -> 0.07 | F22: =C22*E22 -> 0 | G22: =INDEX('AMC & Spares % Assumptions'!$C$5:$C$11, D22) -> 0.095 | H22: =C22*G22 -> 0 | I22: =F22+H22 -> 0
A23: ='Client-Product Master'!B5 -> MAgna Casting & Machine Works Pvt | B23: ='Client-Product Master'!C5 -> 50 Ton Ladle Transfer Car Weighing System | C23: ='Client-Product Master'!E5 -> 0 | D23: 1 | E23: =INDEX('AMC & Spares % Assumptions'!$B$5:$B$11, D23) -> 0.015 | F23: =C23*E23 -> 0 | G23: =INDEX('AMC & Spares % Assumptions'!$C$5:$C$11, D23) -> 0.01 | H23: =C23*G23 -> 0 | I23: =F23+H23 -> 0
A24: ='Client-Product Master'!B5 -> MAgna Casting & Machine Works Pvt | B24: ='Client-Product Master'!C5 -> 50 Ton Ladle Transfer Car Weighing System | C24: ='Client-Product Master'!E5 -> 0 | D24: 2 | E24: =INDEX('AMC & Spares % Assumptions'!$B$5:$B$11, D24) -> 0.03 | F24: =C24*E24 -> 0 | G24: =INDEX('AMC & Spares % Assumptions'!$C$5:$C$11, D24) -> 0.025 | H24: =C24*G24 -> 0 | I24: =F24+H24 -> 0
A25: ='Client-Product Master'!B5 -> MAgna Casting & Machine Works Pvt | B25: ='Client-Product Master'!C5 -> 50 Ton Ladle Transfer Car Weighing System | C25: ='Client-Product Master'!E5 -> 0 | D25: 3 | E25: =INDEX('AMC & Spares % Assumptions'!$B$5:$B$11, D25) -> 0.045 | F25: =C25*E25 -> 0 | G25: =INDEX('AMC & Spares % Assumptions'!$C$5:$C$11, D25) -> 0.045 | H25: =C25*G25 -> 0 | I25: =F25+H25 -> 0
A26: ='Client-Product Master'!B5 -> MAgna Casting & Machine Works Pvt | B26: ='Client-Product Master'!C5 -> 50 Ton Ladle Transfer Car Weighing System | C26: ='Client-Product Master'!E5 -> 0 | D26: 4 | E26: =INDEX('AMC & Spares % Assumptions'!$B$5:$B$11, D26) -> 0.055 | F26: =C26*E26 -> 0 | G26: =INDEX('AMC & Spares % Assumptions'!$C$5:$C$11, D26) -> 0.06 | H26: =C26*G26 -> 0 | I26: =F26+H26 -> 0
A27: ='Client-Product Master'!B5 -> MAgna Casting & Machine Works Pvt | B27: ='Client-Product Master'!C5 -> 50 Ton Ladle Transfer Car Weighing System | C27: ='Client-Product Master'!E5 -> 0 | D27: 5 | E27: =INDEX('AMC & Spares % Assumptions'!$B$5:$B$11, D27) -> 0.06 | F27: =C27*E27 -> 0 | G27: =INDEX('AMC & Spares % Assumptions'!$C$5:$C$11, D27) -> 0.075 | H27: =C27*G27 -> 0 | I27: =F27+H27 -> 0
A28: ='Client-Product Master'!B5 -> MAgna Casting & Machine Works Pvt | B28: ='Client-Product Master'!C5 -> 50 Ton Ladle Transfer Car Weighing System | C28: ='Client-Product Master'!E5 -> 0 | D28: 6 | E28: =INDEX('AMC & Spares % Assumptions'!$B$5:$B$11, D28) -> 0.065 | F28: =C28*E28 -> 0 | G28: =INDEX('AMC & Spares % Assumptions'!$C$5:$C$11, D28) -> 0.085 | H28: =C28*G28 -> 0 | I28: =F28+H28 -> 0
A29: ='Client-Product Master'!B5 -> MAgna Casting & Machine Works Pvt | B29: ='Client-Product Master'!C5 -> 50 Ton Ladle Transfer Car Weighing System | C29: ='Client-Product Master'!E5 -> 0 | D29: 7 | E29: =INDEX('AMC & Spares % Assumptions'!$B$5:$B$11, D29) -> 0.07 | F29: =C29*E29 -> 0 | G29: =INDEX('AMC & Spares % Assumptions'!$C$5:$C$11, D29) -> 0.095 | H29: =C29*G29 -> 0 | I29: =F29+H29 -> 0
A30: ='Client-Product Master'!B6 -> Tata Steel Long products limited | B30: ='Client-Product Master'!C6 -> WEIGHBRIDGE STRUCTURE,100 MT,18X3M | C30: ='Client-Product Master'!E6 -> 0 | D30: 1 | E30: =INDEX('AMC & Spares % Assumptions'!$B$5:$B$11, D30) -> 0.015 | F30: =C30*E30 -> 0 | G30: =INDEX('AMC & Spares % Assumptions'!$C$5:$C$11, D30) -> 0.01 | H30: =C30*G30 -> 0 | I30: =F30+H30 -> 0
A31: ='Client-Product Master'!B6 -> Tata Steel Long products limited | B31: ='Client-Product Master'!C6 -> WEIGHBRIDGE STRUCTURE,100 MT,18X3M | C31: ='Client-Product Master'!E6 -> 0 | D31: 2 | E31: =INDEX('AMC & Spares % Assumptions'!$B$5:$B$11, D31) -> 0.03 | F31: =C31*E31 -> 0 | G31: =INDEX('AMC & Spares % Assumptions'!$C$5:$C$11, D31) -> 0.025 | H31: =C31*G31 -> 0 | I31: =F31+H31 -> 0
A32: ='Client-Product Master'!B6 -> Tata Steel Long products limited | B32: ='Client-Product Master'!C6 -> WEIGHBRIDGE STRUCTURE,100 MT,18X3M | C32: ='Client-Product Master'!E6 -> 0 | D32: 3 | E32: =INDEX('AMC & Spares % Assumptions'!$B$5:$B$11, D32) -> 0.045 | F32: =C32*E32 -> 0 | G32: =INDEX('AMC & Spares % Assumptions'!$C$5:$C$11, D32) -> 0.045 | H32: =C32*G32 -> 0 | I32: =F32+H32 -> 0
A33: ='Client-Product Master'!B6 -> Tata Steel Long products limited | B33: ='Client-Product Master'!C6 -> WEIGHBRIDGE STRUCTURE,100 MT,18X3M | C33: ='Client-Product Master'!E6 -> 0 | D33: 4 | E33: =INDEX('AMC & Spares % Assumptions'!$B$5:$B$11, D33) -> 0.055 | F33: =C33*E33 -> 0 | G33: =INDEX('AMC & Spares % Assumptions'!$C$5:$C$11, D33) -> 0.06 | H33: =C33*G33 -> 0 | I33: =F33+H33 -> 0
A34: ='Client-Product Master'!B6 -> Tata Steel Long products limited | B34: ='Client-Product Master'!C6 -> WEIGHBRIDGE STRUCTURE,100 MT,18X3M | C34: ='Client-Product Master'!E6 -> 0 | D34: 5 | E34: =INDEX('AMC & Spares % Assumptions'!$B$5:$B$11, D34) -> 0.06 | F34: =C34*E34 -> 0 | G34: =INDEX('AMC & Spares % Assumptions'!$C$5:$C$11, D34) -> 0.075 | H34: =C34*G34 -> 0 | I34: =F34+H34 -> 0
A35: ='Client-Product Master'!B6 -> Tata Steel Long products limited | B35: ='Client-Product Master'!C6 -> WEIGHBRIDGE STRUCTURE,100 MT,18X3M | C35: ='Client-Product Master'!E6 -> 0 | D35: 6 | E35: =INDEX('AMC & Spares % Assumptions'!$B$5:$B$11, D35) -> 0.065 | F35: =C35*E35 -> 0 | G35: =INDEX('AMC & Spares % Assumptions'!$C$5:$C$11, D35) -> 0.085 | H35: =C35*G35 -> 0 | I35: =F35+H35 -> 0
A36: ='Client-Product Master'!B6 -> Tata Steel Long products limited | B36: ='Client-Product Master'!C6 -> WEIGHBRIDGE STRUCTURE,100 MT,18X3M | C36: ='Client-Product Master'!E6 -> 0 | D36: 7 | E36: =INDEX('AMC & Spares % Assumptions'!$B$5:$B$11, D36) -> 0.07 | F36: =C36*E36 -> 0 | G36: =INDEX('AMC & Spares % Assumptions'!$C$5:$C$11, D36) -> 0.095 | H36: =C36*G36 -> 0 | I36: =F36+H36 -> 0
A37: ='Client-Product Master'!B7 -> Hospet Steels Limited | B37: ='Client-Product Master'!C7 -> Hot metal weighing system 100 ton | C37: ='Client-Product Master'!E7 -> 0 | D37: 1 | E37: =INDEX('AMC & Spares % Assumptions'!$B$5:$B$11, D37) -> 0.015 | F37: =C37*E37 -> 0 | G37: =INDEX('AMC & Spares % Assumptions'!$C$5:$C$11, D37) -> 0.01 | H37: =C37*G37 -> 0 | I37: =F37+H37 -> 0
A38: ='Client-Product Master'!B7 -> Hospet Steels Limited | B38: ='Client-Product Master'!C7 -> Hot metal weighing system 100 ton | C38: ='Client-Product Master'!E7 -> 0 | D38: 2 | E38: =INDEX('AMC & Spares % Assumptions'!$B$5:$B$11, D38) -> 0.03 | F38: =C38*E38 -> 0 | G38: =INDEX('AMC & Spares % Assumptions'!$C$5:$C$11, D38) -> 0.025 | H38: =C38*G38 -> 0 | I38: =F38+H38 -> 0
A39: ='Client-Product Master'!B7 -> Hospet Steels Limited | B39: ='Client-Product Master'!C7 -> Hot metal weighing system 100 ton | C39: ='Client-Product Master'!E7 -> 0 | D39: 3 | E39: =INDEX('AMC & Spares % Assumptions'!$B$5:$B$11, D39) -> 0.045 | F39: =C39*E39 -> 0 | G39: =INDEX('AMC & Spares % Assumptions'!$C$5:$C$11, D39) -> 0.045 | H39: =C39*G39 -> 0 | I39: =F39+H39 -> 0
A40: ='Client-Product Master'!B7 -> Hospet Steels Limited | B40: ='Client-Product Master'!C7 -> Hot metal weighing system 100 ton | C40: ='Client-Product Master'!E7 -> 0 | D40: 4 | E40: =INDEX('AMC & Spares % Assumptions'!$B$5:$B$11, D40) -> 0.055 | F40: =C40*E40 -> 0 | G40: =INDEX('AMC & Spares % Assumptions'!$C$5:$C$11, D40) -> 0.06 | H40: =C40*G40 -> 0 | I40: =F40+H40 -> 0
...

Sheet Client Summary
A1: Client Name | B1: Number of Products | C1: Total Billed Value (INR) | D1: Total 7-Yr AMC Opportunity (INR) | E1: Total 7-Yr Spares Opportunity (INR) | F1: Total 7-Yr Aftermarket Opportunity (INR)
A2: JSW STEEL-SALEM | B2: =COUNTIF('Client-Product Master'!$B$2:$B$55, A2) -> 1 | C2: =SUMIF('Client-Product Master'!$B$2:$B$55, A2, 'Client-Product Master'!$E$2:$E$55) -> 930000 | D2: =SUMIF('Opportunity Model (Year-wise)'!$A$2:$A$379, A2, 'Opportunity Model (Year-wise)'!$F$2:$F$379) -> 316200 | E2: =SUMIF('Opportunity Model (Year-wise)'!$A$2:$A$379, A2, 'Opportunity Model (Year-wise)'!$H$2:$H$379) -> 367350 | F2: =D2+E2 -> 683550
A3: JSW BPSL | B3: =COUNTIF('Client-Product Master'!$B$2:$B$55, A3) -> 2 | C3: =SUMIF('Client-Product Master'!$B$2:$B$55, A3, 'Client-Product Master'!$E$2:$E$55) -> 870000 | D3: =SUMIF('Opportunity Model (Year-wise)'!$A$2:$A$379, A3, 'Opportunity Model (Year-wise)'!$F$2:$F$379) -> 295800 | E3: =SUMIF('Opportunity Model (Year-wise)'!$A$2:$A$379, A3, 'Opportunity Model (Year-wise)'!$H$2:$H$379) -> 343650 | F3: =D3+E3 -> 639450
A4: JSW JFE Steel Limited | B4: =COUNTIF('Client-Product Master'!$B$2:$B$55, A4) -> 1 | C4: =SUMIF('Client-Product Master'!$B$2:$B$55, A4, 'Client-Product Master'!$E$2:$E$55) -> 860000 | D4: =SUMIF('Opportunity Model (Year-wise)'!$A$2:$A$379, A4, 'Opportunity Model (Year-wise)'!$F$2:$F$379) -> 292400 | E4: =SUMIF('Opportunity Model (Year-wise)'!$A$2:$A$379, A4, 'Opportunity Model (Year-wise)'!$H$2:$H$379) -> 339700 | F4: =D4+E4 -> 632100
A5: TAMILIIADU CEMENTS CORPORATION LTD | B5: =COUNTIF('Client-Product Master'!$B$2:$B$55, A5) -> 1 | C5: =SUMIF('Client-Product Master'!$B$2:$B$55, A5, 'Client-Product Master'!$E$2:$E$55) -> 675000 | D5: =SUMIF('Opportunity Model (Year-wise)'!$A$2:$A$379, A5, 'Opportunity Model (Year-wise)'!$F$2:$F$379) -> 229500 | E5: =SUMIF('Opportunity Model (Year-wise)'!$A$2:$A$379, A5, 'Opportunity Model (Year-wise)'!$H$2:$H$379) -> 266625 | F5: =D5+E5 -> 496125
A6: (Client name not provided in source - confirm) | B6: =COUNTIF('Client-Product Master'!$B$2:$B$55, A6) -> 1 | C6: =SUMIF('Client-Product Master'!$B$2:$B$55, A6, 'Client-Product Master'!$E$2:$E$55) -> 660000 | D6: =SUMIF('Opportunity Model (Year-wise)'!$A$2:$A$379, A6, 'Opportunity Model (Year-wise)'!$F$2:$F$379) -> 224400 | E6: =SUMIF('Opportunity Model (Year-wise)'!$A$2:$A$379, A6, 'Opportunity Model (Year-wise)'!$H$2:$H$379) -> 260700 | F6: =D6+E6 -> 485100
A7: Ultratech Cement Ltd, Unit- Maihar cement works | B7: =COUNTIF('Client-Product Master'!$B$2:$B$55, A7) -> 1 | C7: =SUMIF('Client-Product Master'!$B$2:$B$55, A7, 'Client-Product Master'!$E$2:$E$55) -> 550000 | D7: =SUMIF('Opportunity Model (Year-wise)'!$A$2:$A$379, A7, 'Opportunity Model (Year-wise)'!$F$2:$F$379) -> 187000 | E7: =SUMIF('Opportunity Model (Year-wise)'!$A$2:$A$379, A7, 'Opportunity Model (Year-wise)'!$H$2:$H$379) -> 217250 | F7: =D7+E7 -> 404250
A8: Kirloskar Ferrous Industries Ltd Steel Plant | B8: =COUNTIF('Client-Product Master'!$B$2:$B$55, A8) -> 1 | C8: =SUMIF('Client-Product Master'!$B$2:$B$55, A8, 'Client-Product Master'!$E$2:$E$55) -> 400000 | D8: =SUMIF('Opportunity Model (Year-wise)'!$A$2:$A$379, A8, 'Opportunity Model (Year-wise)'!$F$2:$F$379) -> 136000 | E8: =SUMIF('Opportunity Model (Year-wise)'!$A$2:$A$379, A8, 'Opportunity Model (Year-wise)'!$H$2:$H$379) -> 158000 | F8: =D8+E8 -> 294000
A9: Balaji Engineers & Contractors. | B9: =COUNTIF('Client-Product Master'!$B$2:$B$55, A9) -> 1 | C9: =SUMIF('Client-Product Master'!$B$2:$B$55, A9, 'Client-Product Master'!$E$2:$E$55) -> 333250 | D9: =SUMIF('Opportunity Model (Year-wise)'!$A$2:$A$379, A9, 'Opportunity Model (Year-wise)'!$F$2:$F$379) -> 113305 | E9: =SUMIF('Opportunity Model (Year-wise)'!$A$2:$A$379, A9, 'Opportunity Model (Year-wise)'!$H$2:$H$379) -> 131633.75 | F9: =D9+E9 -> 244938.75
A10: Evonith Steel Complex | B10: =COUNTIF('Client-Product Master'!$B$2:$B$55, A10) -> 1 | C10: =SUMIF('Client-Product Master'!$B$2:$B$55, A10, 'Client-Product Master'!$E$2:$E$55) -> 295000 | D10: =SUMIF('Opportunity Model (Year-wise)'!$A$2:$A$379, A10, 'Opportunity Model (Year-wise)'!$F$2:$F$379) -> 100300 | E10: =SUMIF('Opportunity Model (Year-wise)'!$A$2:$A$379, A10, 'Opportunity Model (Year-wise)'!$H$2:$H$379) -> 116525 | F10: =D10+E10 -> 216825
A11: adani gondia | B11: =COUNTIF('Client-Product Master'!$B$2:$B$55, A11) -> 1 | C11: =SUMIF('Client-Product Master'!$B$2:$B$55, A11, 'Client-Product Master'!$E$2:$E$55) -> 165000 | D11: =SUMIF('Opportunity Model (Year-wise)'!$A$2:$A$379, A11, 'Opportunity Model (Year-wise)'!$F$2:$F$379) -> 56100 | E11: =SUMIF('Opportunity Model (Year-wise)'!$A$2:$A$379, A11, 'Opportunity Model (Year-wise)'!$H$2:$H$379) -> 65175 | F11: =D11+E11 -> 121275
A12: JSW Steel Ltd. | B12: =COUNTIF('Client-Product Master'!$B$2:$B$55, A12) -> 1 | C12: =SUMIF('Client-Product Master'!$B$2:$B$55, A12, 'Client-Product Master'!$E$2:$E$55) -> 113000 | D12: =SUMIF('Opportunity Model (Year-wise)'!$A$2:$A$379, A12, 'Opportunity Model (Year-wise)'!$F$2:$F$379) -> 38420 | E12: =SUMIF('Opportunity Model (Year-wise)'!$A$2:$A$379, A12, 'Opportunity Model (Year-wise)'!$H$2:$H$379) -> 44635 | F12: =D12+E12 -> 83055
A13: JSW Steel Limited | B13: =COUNTIF('Client-Product Master'!$B$2:$B$55, A13) -> 4 | C13: =SUMIF('Client-Product Master'!$B$2:$B$55, A13, 'Client-Product Master'!$E$2:$E$55) -> 90000 | D13: =SUMIF('Opportunity Model (Year-wise)'!$A$2:$A$379, A13, 'Opportunity Model (Year-wise)'!$F$2:$F$379) -> 30600 | E13: =SUMIF('Opportunity Model (Year-wise)'!$A$2:$A$379, A13, 'Opportunity Model (Year-wise)'!$H$2:$H$379) -> 35550 | F13: =D13+E13 -> 66150
... A44: Yash Trading Co | B44: =COUNTIF('Client-Product Master'!$B$2:$B$55, A44) -> 2 | C44: =SUMIF('Client-Product Master'!$B$2:$B$55, A44, 'Client-Product Master'!$E$2:$E$55) -> 0 | D44: =SUMIF('Opportunity Model (Year-wise)'!$A$2:$A$379, A44, 'Opportunity Model (Year-wise)'!$F$2:$F$379) -> 0 | E44: =SUMIF('Opportunity Model (Year-wise)'!$A$2:$A$379, A44, 'Opportunity Model (Year-wise)'!$H$2:$H$379) -> 0 | F44: =D44+E44 -> 0
A45: GRAND TOTAL | B45: =SUM(B2:B44) -> 54 | C45: =SUM(C2:C44) -> 5963250 | D45: =SUM(D2:D44) -> 2027505 | E45: =SUM(E2:E44) -> 2355483.8 | F45: =SUM(F2:F44) -> 4382988.8
